Workbook
Name _Toc438040364: #REF!
Name _Toc438040364: #REF!
Name _Toc438040364: #REF!
Name _Toc438040364: #REF!
Name _Toc438040364: #REF!
Name _Toc438040364: #REF!
Name _Toc438040364: #REF!
Name _Toc438040364: #REF!
Name _Toc499885850: '[1] 內政'!#REF!
Name _Toc499885850: '[2] 司法法制'!#REF!
Name _Toc499885850: '[3] 財政'!#REF!
Name _Toc499885850: #REF!
Name _Toc499885850: [4]交通!#REF!
Name _Toc499885850: [5]社福衛環!#REF!
Name _Toc499885850: [6]教育文化!#REF!
Name _Toc499885850: [7]經濟!#REF!
Name _Toc501127871: #REF!
Name _Toc501127871: #REF!
Name _Toc501127871: #REF!
Name _Toc501127871: #REF!
Name _Toc501127871: #REF!
Name _Toc501127871: #REF!
Name _Toc501127871: #REF!
Name _Toc501127871: #REF!
Name _Toc502678091: #REF!
Name _Toc502678091: #REF!
Name _Toc502678091: #REF!
Name _Toc502678091: #REF!
Name _Toc502678091: #REF!
Name _Toc502678091: #REF!
Name _Toc502678091: #REF!
Name _Toc502678091: #REF!
Name 出_席: #REF!

Sheet 分數表
A1: 內政
C2: 政黨 | D2: 民進黨 | E2: 民進黨 | F2: 民進黨 | G2: 民進黨 | H2: 民進黨 | I2: 民進黨 | J2: 國民黨 | K2: 國民黨 | L2: 國民黨 | M2: 國民黨 | N2: 國民黨 | O2: 國民黨 | P2: 民眾黨 | Q2: 無黨籍
A3: 平均 | B3: 去召委平均 | C3: 委員姓名 | D3: 張宏陸 | E3: 吳琪銘 | F3: 王美惠 | G3: 蘇巧慧 | H3: 李柏毅 | I3: 黃捷 | J3: 牛煦庭 | K3: 徐欣瑩 | L3: 黃建賓 | M3: 張智倫 | N3: 許宇甄 | O3: 丁學忠 | P3: 麥玉珍 | Q3: 高金素梅
A4: =AVERAGE(D4:Q4) -> 5.7142857 | B4: =AVERAGE(E4,F4:I4,K4:Q4) -> 5.8333333 | C4: 次數 | D4: =' 內政'!D26 -> 10 | E4: =' 內政'!F26 -> 1 | F4: =' 內政'!H26 -> 40 | G4: =' 內政'!J26 -> 4 | H4: =' 內政'!L26 -> 3 | I4: =' 內政'!N26 -> 5 | J4: =' 內政'!P26 -> 0 | K4: =' 內政'!R26 -> 0 | L4: =' 內政'!T26 -> 0 | M4: =' 內政'!V26 -> 1 | N4: =' 內政'!X26 -> 4 | O4: =' 內政'!Z26 -> 0 | P4: =' 內政'!AB26 -> 12 | Q4: =' 內政'!AD26 -> 0
A5: =AVERAGE(D5:Q5) -> 474.85714 | B5: =AVERAGE(E5,F5:I5,K5:Q5) -> 496.58333 | C5: 字數 | D5: =' 內政'!E26 -> 689 | E5: =' 內政'!G26 -> 231 | F5: =' 內政'!I26 -> 1151 | G5: =' 內政'!K26 -> 795 | H5: =' 內政'!M26 -> 588 | I5: =' 內政'!O26 -> 718 | J5: =' 內政'!Q26 -> 0 | K5: =' 內政'!S26 -> 0 | L5: =' 內政'!U26 -> 0 | M5: =' 內政'!W26 -> 278 | N5: =' 內政'!Y26 -> 577 | O5: =' 內政'!AA26 -> 0 | P5: =' 內政'!AC26 -> 1621 | Q5: =' 內政'!AE26 -> 0
A6: 全統計參與(滿分五分) | D6: =IF(SQRT((D4/$A4)^2+(D5/$A5)^2)>2,5,5*SQRT((D4/$A4)^2+(D5/$A5)^2)/2) -> 5 | E6: =IF(SQRT((E4/$A4)^2+(E5/$A5)^2)>2,5,5*SQRT((E4/$A4)^2+(E5/$A5)^2)/2) -> 1.292455 | F6: =IF(SQRT((F4/$A4)^2+(F5/$A5)^2)>2,5,5*SQRT((F4/$A4)^2+(F5/$A5)^2)/2) -> 5 | G6: =IF(SQRT((G4/$A4)^2+(G5/$A5)^2)>2,5,5*SQRT((G4/$A4)^2+(G5/$A5)^2)/2) -> 4.5365905 | H6: =IF(SQRT((H4/$A4)^2+(H5/$A5)^2)>2,5,5*SQRT((H4/$A4)^2+(H5/$A5)^2)/2) -> 3.3624122 | I6: =IF(SQRT((I4/$A4)^2+(I5/$A5)^2)>2,5,5*SQRT((I4/$A4)^2+(I5/$A5)^2)/2) -> 4.3674012 | J6: =IF(SQRT((J4/$A4)^2+(J5/$A5)^2)>2,5,5*SQRT((J4/$A4)^2+(J5/$A5)^2)/2) -> 0 | K6: =IF(SQRT((K4/$A4)^2+(K5/$A5)^2)>2,5,5*SQRT((K4/$A4)^2+(K5/$A5)^2)/2) -> 0 | ... Q6: =IF(SQRT((Q4/$A4)^2+(Q5/$A5)^2)>2,5,5*SQRT((Q4/$A4)^2+(Q5/$A5)^2)/2) -> 0
A7: 去召委統計參與(滿分五分) | D7: =IF(SQRT((D4/$B4)^2+(D5/$B5)^2)>2,5,5*SQRT((D4/$B4)^2+(D5/$B5)^2)/2) -> 5 | E7: =IF(SQRT((E4/$B4)^2+(E5/$B5)^2)>2,5,5*SQRT((E4/$B4)^2+(E5/$B5)^2)/2) -> 1.2394026 | F7: =IF(SQRT((F4/$B4)^2+(F5/$B5)^2)>2,5,5*SQRT((F4/$B4)^2+(F5/$B5)^2)/2) -> 5 | G7: =IF(SQRT((G4/$B4)^2+(G5/$B5)^2)>2,5,5*SQRT((G4/$B4)^2+(G5/$B5)^2)/2) -> 4.3540299 | H7: =IF(SQRT((H4/$B4)^2+(H5/$B5)^2)>2,5,5*SQRT((H4/$B4)^2+(H5/$B5)^2)/2) -> 3.2273848 | I7: =IF(SQRT((I4/$B4)^2+(I5/$B5)^2)>2,5,5*SQRT((I4/$B4)^2+(I5/$B5)^2)/2) -> 4.2021299 | J7: =IF(SQRT((J4/$B4)^2+(J5/$B5)^2)>2,5,5*SQRT((J4/$B4)^2+(J5/$B5)^2)/2) -> 0 | K7: =IF(SQRT((K4/$B4)^2+(K5/$B5)^2)>2,5,5*SQRT((K4/$B4)^2+(K5/$B5)^2)/2) -> 0 | ... Q7: =IF(SQRT((Q4/$B4)^2+(Q5/$B5)^2)>2,5,5*SQRT((Q4/$B4)^2+(Q5/$B5)^2)/2) -> 0
A8: 全統計參與(滿分三分) | D8: =IF(SQRT((D4/$A4)^2+(D5/$A5)^2)>2,3,3*SQRT((D4/$A4)^2+(D5/$A5)^2)/2) -> 3 | E8: =IF(SQRT((E4/$A4)^2+(E5/$A5)^2)>2,3,3*SQRT((E4/$A4)^2+(E5/$A5)^2)/2) -> 0.77547297 | F8: =IF(SQRT((F4/$A4)^2+(F5/$A5)^2)>2,3,3*SQRT((F4/$A4)^2+(F5/$A5)^2)/2) -> 3 | G8: =IF(SQRT((G4/$A4)^2+(G5/$A5)^2)>2,3,3*SQRT((G4/$A4)^2+(G5/$A5)^2)/2) -> 2.7219543 | H8: =IF(SQRT((H4/$A4)^2+(H5/$A5)^2)>2,3,3*SQRT((H4/$A4)^2+(H5/$A5)^2)/2) -> 2.0174473 | I8: =IF(SQRT((I4/$A4)^2+(I5/$A5)^2)>2,3,3*SQRT((I4/$A4)^2+(I5/$A5)^2)/2) -> 2.6204407 | J8: =IF(SQRT((J4/$A4)^2+(J5/$A5)^2)>2,3,3*SQRT((J4/$A4)^2+(J5/$A5)^2)/2) -> 0 | K8: =IF(SQRT((K4/$A4)^2+(K5/$A5)^2)>2,3,3*SQRT((K4/$A4)^2+(K5/$A5)^2)/2) -> 0 | ... Q8: =IF(SQRT((Q4/$A4)^2+(Q5/$A5)^2)>2,3,3*SQRT((Q4/$A4)^2+(Q5/$A5)^2)/2) -> 0
A9: 去召委統計參與(滿分三分) | D9: =IF(SQRT((D4/$B4)^2+(D5/$B5)^2)>2,3,3*SQRT((D4/$B4)^2+(D5/$B5)^2)/2) -> 3 | E9: =IF(SQRT((E4/$B4)^2+(E5/$B5)^2)>2,3,3*SQRT((E4/$B4)^2+(E5/$B5)^2)/2) -> 0.74364154 | F9: =IF(SQRT((F4/$B4)^2+(F5/$B5)^2)>2,3,3*SQRT((F4/$B4)^2+(F5/$B5)^2)/2) -> 3 | G9: =IF(SQRT((G4/$B4)^2+(G5/$B5)^2)>2,3,3*SQRT((G4/$B4)^2+(G5/$B5)^2)/2) -> 2.6124179 | H9: =IF(SQRT((H4/$B4)^2+(H5/$B5)^2)>2,3,3*SQRT((H4/$B4)^2+(H5/$B5)^2)/2) -> 1.9364309 | I9: =IF(SQRT((I4/$B4)^2+(I5/$B5)^2)>2,3,3*SQRT((I4/$B4)^2+(I5/$B5)^2)/2) -> 2.521278 | J9: =IF(SQRT((J4/$B4)^2+(J5/$B5)^2)>2,3,3*SQRT((J4/$B4)^2+(J5/$B5)^2)/2) -> 0 | K9: =IF(SQRT((K4/$B4)^2+(K5/$B5)^2)>2,3,3*SQRT((K4/$B4)^2+(K5/$B5)^2)/2) -> 0 | ... Q9: =IF(SQRT((Q4/$B4)^2+(Q5/$B5)^2)>2,3,3*SQRT((Q4/$B4)^2+(Q5/$B5)^2)/2) -> 0
A11: 外交國防
C12: 政黨 | D12: 民進黨 | E12: 民進黨 | F12: 民進黨 | G12: 民進黨 | H12: 民進黨 | I12: 民進黨 | J12: 國民黨 | K12: 國民黨 | L12: 國民黨 | M12: 國民黨 | N12: 國民黨 | O12: 國民黨 | P12: 民眾黨
A13: 平均 | B13: 去召委平均 | C13: 委員姓名 | D13: 沈伯洋 | E13: 王定宇 | F13: 陳冠廷 | G13: 陳俊宇 | H13: 羅美玲 | I13: 林楚茵 | J13: 黃仁 | K13: 韓國瑜 | L13: 江啟臣 | M13: 馬文君 | N13: 徐巧芯 | O13: 陳永康 | P13: 林憶君
A14: =AVERAGE(D14:P14) -> 0 | B14: =AVERAGE(E14:G14,H14:I14,M14:P14) -> 0 | C14: 次數 | D14: =外交國防!D14 -> 0 | E14: =外交國防!F14 -> 0 | F14: =外交國防!H14 -> 0 | G14: =外交國防!J14 -> 0 | H14: =外交國防!L14 -> 0 | I14: =外交國防!N14 -> 0 | J14: =外交國防!P14 -> 0 | K14: =外交國防!R14 -> 0 | L14: =外交國防!T14 -> 0 | M14: =外交國防!V14 -> 0 | N14: =外交國防!X14 -> 0 | O14: =外交國防!Z14 -> 0 | P14: =外交國防!AB14 -> 0
A15: =AVERAGE(D15:P15) -> 0 | B15: =AVERAGE(E15:G15,H15:I15,M15:P15) -> 0 | C15: 字數 | D15: =外交國防!E14 -> 0 | E15: =外交國防!G14 -> 0 | F15: =外交國防!I14 -> 0 | G15: =外交國防!K14 -> 0 | H15: =外交國防!M14 -> 0 | I15: =外交國防!O14 -> 0 | J15: =外交國防!Q14 -> 0 | K15: =外交國防!S14 -> 0 | L15: =外交國防!U14 -> 0 | M15: =外交國防!W14 -> 0 | N15: =外交國防!Y14 -> 0 | O15: =外交國防!AA14 -> 0 | P15: =外交國防!AC14 -> 0
A16: 全統計參與(滿分五分) | D16: =IF(SQRT((D14/$A14)^2+(D15/$A15)^2)>2,5,5*SQRT((D14/$A14)^2+(D15/$A15)^2)/2) -> #DIV/0! | E16: =IF(SQRT((E14/$A14)^2+(E15/$A15)^2)>2,5,5*SQRT((E14/$A14)^2+(E15/$A15)^2)/2) -> #DIV/0! | F16: =IF(SQRT((F14/$A14)^2+(F15/$A15)^2)>2,5,5*SQRT((F14/$A14)^2+(F15/$A15)^2)/2) -> #DIV/0! | G16: =IF(SQRT((G14/$A14)^2+(G15/$A15)^2)>2,5,5*SQRT((G14/$A14)^2+(G15/$A15)^2)/2) -> #DIV/0! | H16: =IF(SQRT((H14/$A14)^2+(H15/$A15)^2)>2,5,5*SQRT((H14/$A14)^2+(H15/$A15)^2)/2) -> #DIV/0! | I16: =IF(SQRT((I14/$A14)^2+(I15/$A15)^2)>2,5,5*SQRT((I14/$A14)^2+(I15/$A15)^2)/2) -> #DIV/0! | J16: =IF(SQRT((J14/$A14)^2+(J15/$A15)^2)>2,5,5*SQRT((J14/$A14)^2+(J15/$A15)^2)/2) -> #DIV/0! | K16: =IF(SQRT((K14/$A14)^2+(K15/$A15)^2)>2,5,5*SQRT((K14/$A14)^2+(K15/$A15)^2)/2) -> #DIV/0! | ... P16: =IF(SQRT((P14/$A14)^2+(P15/$A15)^2)>2,5,5*SQRT((P14/$A14)^2+(P15/$A15)^2)/2) -> #DIV/0!
A17: 去召委統計參與(滿分五分) | D17: =IF(SQRT((D14/$B14)^2+(D15/$B15)^2)>2,5,5*SQRT((D14/$B14)^2+(D15/$B15)^2)/2) -> #DIV/0! | E17: =IF(SQRT((E14/$B14)^2+(E15/$B15)^2)>2,5,5*SQRT((E14/$B14)^2+(E15/$B15)^2)/2) -> #DIV/0! | F17: =IF(SQRT((F14/$B14)^2+(F15/$B15)^2)>2,5,5*SQRT((F14/$B14)^2+(F15/$B15)^2)/2) -> #DIV/0! | G17: =IF(SQRT((G14/$B14)^2+(G15/$B15)^2)>2,5,5*SQRT((G14/$B14)^2+(G15/$B15)^2)/2) -> #DIV/0! | H17: =IF(SQRT((H14/$B14)^2+(H15/$B15)^2)>2,5,5*SQRT((H14/$B14)^2+(H15/$B15)^2)/2) -> #DIV/0! | I17: =IF(SQRT((I14/$B14)^2+(I15/$B15)^2)>2,5,5*SQRT((I14/$B14)^2+(I15/$B15)^2)/2) -> #DIV/0! | J17: =IF(SQRT((J14/$B14)^2+(J15/$B15)^2)>2,5,5*SQRT((J14/$B14)^2+(J15/$B15)^2)/2) -> #DIV/0! | K17: =IF(SQRT((K14/$B14)^2+(K15/$B15)^2)>2,5,5*SQRT((K14/$B14)^2+(K15/$B15)^2)/2) -> #DIV/0! | ... P17: =IF(SQRT((P14/$B14)^2+(P15/$B15)^2)>2,5,5*SQRT((P14/$B14)^2+(P15/$B15)^2)/2) -> #DIV/0!
A18: 全統計參與(滿分三分) | D18: =IF(SQRT((D14/$A14)^2+(D15/$A15)^2)>2,3,3*SQRT((D14/$A14)^2+(D15/$A15)^2)/2) -> #DIV/0! | E18: =IF(SQRT((E14/$A14)^2+(E15/$A15)^2)>2,3,3*SQRT((E14/$A14)^2+(E15/$A15)^2)/2) -> #DIV/0! | F18: =IF(SQRT((F14/$A14)^2+(F15/$A15)^2)>2,3,3*SQRT((F14/$A14)^2+(F15/$A15)^2)/2) -> #DIV/0! | G18: =IF(SQRT((G14/$A14)^2+(G15/$A15)^2)>2,3,3*SQRT((G14/$A14)^2+(G15/$A15)^2)/2) -> #DIV/0! | H18: =IF(SQRT((H14/$A14)^2+(H15/$A15)^2)>2,3,3*SQRT((H14/$A14)^2+(H15/$A15)^2)/2) -> #DIV/0! | I18: =IF(SQRT((I14/$A14)^2+(I15/$A15)^2)>2,3,3*SQRT((I14/$A14)^2+(I15/$A15)^2)/2) -> #DIV/0! | J18: =IF(SQRT((J14/$A14)^2+(J15/$A15)^2)>2,3,3*SQRT((J14/$A14)^2+(J15/$A15)^2)/2) -> #DIV/0! | K18: =IF(SQRT((K14/$A14)^2+(K15/$A15)^2)>2,3,3*SQRT((K14/$A14)^2+(K15/$A15)^2)/2) -> #DIV/0! | ... P18: =IF(SQRT((P14/$A14)^2+(P15/$A15)^2)>2,3,3*SQRT((P14/$A14)^2+(P15/$A15)^2)/2) -> #DIV/0!
A19: 去召委統計參與(滿分三分) | D19: =IF(SQRT((D14/$B14)^2+(D15/$B15)^2)>2,3,3*SQRT((D14/$B14)^2+(D15/$B15)^2)/2) -> #DIV/0! | E19: =IF(SQRT((E14/$B14)^2+(E15/$B15)^2)>2,3,3*SQRT((E14/$B14)^2+(E15/$B15)^2)/2) -> #DIV/0! | F19: =IF(SQRT((F14/$B14)^2+(F15/$B15)^2)>2,3,3*SQRT((F14/$B14)^2+(F15/$B15)^2)/2) -> #DIV/0! | G19: =IF(SQRT((G14/$B14)^2+(G15/$B15)^2)>2,3,3*SQRT((G14/$B14)^2+(G15/$B15)^2)/2) -> #DIV/0! | H19: =IF(SQRT((H14/$B14)^2+(H15/$B15)^2)>2,3,3*SQRT((H14/$B14)^2+(H15/$B15)^2)/2) -> #DIV/0! | I19: =IF(SQRT((I14/$B14)^2+(I15/$B15)^2)>2,3,3*SQRT((I14/$B14)^2+(I15/$B15)^2)/2) -> #DIV/0! | J19: =IF(SQRT((J14/$B14)^2+(J15/$B15)^2)>2,3,3*SQRT((J14/$B14)^2+(J15/$B15)^2)/2) -> #DIV/0! | K19: =IF(SQRT((K14/$B14)^2+(K15/$B15)^2)>2,3,3*SQRT((K14/$B14)^2+(K15/$B15)^2)/2) -> #DIV/0! | ... P19: =IF(SQRT((P14/$B14)^2+(P15/$B15)^2)>2,3,3*SQRT((P14/$B14)^2+(P15/$B15)^2)/2) -> #DIV/0!
K20: 院長 | L20: 副院長
A21: 經濟
C22: 政黨 | D22: 民進黨 | E22: 民進黨 | F22: 民進黨 | G22: 民進黨 | H22: 民進黨 | I22: 民進黨 | J22: 國民黨 | K22: 國民黨 | L22: 國民黨 | M22: 國民黨 | N22: 國民黨 | O22: 國民黨 | P22: 民眾黨 | Q22: 無黨籍
A23: 平均 | B23: 去召委平均 | C23: 委員姓名 | D23: 蔡易餘 | E23: 林岱樺 | F23: 邱議瑩 | G23: 邱志偉 | H23: 陳亭妃 | I23: 賴瑞隆 | J23: 謝衣鳯 | K23: 楊瓊瓔 | L23: 鄭天財 | M23: 呂玉玲 | N23: 張嘉郡 | O23: 鄭正鈐 | P23: 張啓楷 | Q23: 陳超明
A24: =AVERAGE(D24:R24) -> 0 | B24: =AVERAGE(E24:F24,G24:I24,K24:Q24) -> 0 | C24: 次數 | D24: =經濟!D13 -> 0 | E24: =經濟!F13 -> 0 | F24: =經濟!H13 -> 0 | G24: =經濟!J13 -> 0 | H24: =經濟!L13 -> 0 | I24: =經濟!N13 -> 0 | J24: =經濟!P13 -> 0 | K24: =經濟!R13 -> 0 | L24: =經濟!T13 -> 0 | M24: =經濟!V13 -> 0 | N24: =經濟!X13 -> 0 | O24: =經濟!Z13 -> 0 | P24: =經濟!AB13 -> 0 | Q24: =經濟!AD13 -> 0
A25: =AVERAGE(D25:R25) -> 0 | B25: =AVERAGE(E25:F25,G25:I25,K25:Q25) -> 0 | C25: 字數 | D25: =經濟!E13 -> 0 | E25: =經濟!G13 -> 0 | F25: =經濟!I13 -> 0 | G25: =經濟!K13 -> 0 | H25: =經濟!M13 -> 0 | I25: =經濟!O13 -> 0 | J25: =經濟!Q13 -> 0 | K25: =經濟!S13 -> 0 | L25: =經濟!U13 -> 0 | M25: =經濟!W13 -> 0 | N25: =經濟!Y13 -> 0 | O25: =經濟!AA13 -> 0 | P25: =經濟!AC13 -> 0 | Q25: =經濟!AE13 -> 0
A26: 全統計參與(滿分五分) | D26: =IF(SQRT((D24/$A24)^2+(D25/$A25)^2)>2,5,5*SQRT((D24/$A24)^2+(D25/$A25)^2)/2) -> #DIV/0! | E26: =IF(SQRT((E24/$A24)^2+(E25/$A25)^2)>2,5,5*SQRT((E24/$A24)^2+(E25/$A25)^2)/2) -> #DIV/0! | F26: =IF(SQRT((F24/$A24)^2+(F25/$A25)^2)>2,5,5*SQRT((F24/$A24)^2+(F25/$A25)^2)/2) -> #DIV/0! | G26: =IF(SQRT((G24/$A24)^2+(G25/$A25)^2)>2,5,5*SQRT((G24/$A24)^2+(G25/$A25)^2)/2) -> #DIV/0! | H26: =IF(SQRT((H24/$A24)^2+(H25/$A25)^2)>2,5,5*SQRT((H24/$A24)^2+(H25/$A25)^2)/2) -> #DIV/0! | I26: =IF(SQRT((I24/$A24)^2+(I25/$A25)^2)>2,5,5*SQRT((I24/$A24)^2+(I25/$A25)^2)/2) -> #DIV/0! | J26: =IF(SQRT((J24/$A24)^2+(J25/$A25)^2)>2,5,5*SQRT((J24/$A24)^2+(J25/$A25)^2)/2) -> #DIV/0! | K26: =IF(SQRT((K24/$A24)^2+(K25/$A25)^2)>2,5,5*SQRT((K24/$A24)^2+(K25/$A25)^2)/2) -> #DIV/0! | ... Q26: =IF(SQRT((Q24/$A24)^2+(Q25/$A25)^2)>2,5,5*SQRT((Q24/$A24)^2+(Q25/$A25)^2)/2) -> #DIV/0!
A27: 去召委統計參與(滿分五分) | D27: =IF(SQRT((D24/$B24)^2+(D25/$B25)^2)>2,5,5*SQRT((D24/$B24)^2+(D25/$B25)^2)/2) -> #DIV/0! | E27: =IF(SQRT((E24/$B24)^2+(E25/$B25)^2)>2,5,5*SQRT((E24/$B24)^2+(E25/$B25)^2)/2) -> #DIV/0! | F27: =IF(SQRT((F24/$B24)^2+(F25/$B25)^2)>2,5,5*SQRT((F24/$B24)^2+(F25/$B25)^2)/2) -> #DIV/0! | G27: =IF(SQRT((G24/$B24)^2+(G25/$B25)^2)>2,5,5*SQRT((G24/$B24)^2+(G25/$B25)^2)/2) -> #DIV/0! | H27: =IF(SQRT((H24/$B24)^2+(H25/$B25)^2)>2,5,5*SQRT((H24/$B24)^2+(H25/$B25)^2)/2) -> #DIV/0! | I27: =IF(SQRT((I24/$B24)^2+(I25/$B25)^2)>2,5,5*SQRT((I24/$B24)^2+(I25/$B25)^2)/2) -> #DIV/0! | J27: =IF(SQRT((J24/$B24)^2+(J25/$B25)^2)>2,5,5*SQRT((J24/$B24)^2+(J25/$B25)^2)/2) -> #DIV/0! | K27: =IF(SQRT((K24/$B24)^2+(K25/$B25)^2)>2,5,5*SQRT((K24/$B24)^2+(K25/$B25)^2)/2) -> #DIV/0! | ... Q27: =IF(SQRT((Q24/$B24)^2+(Q25/$B25)^2)>2,5,5*SQRT((Q24/$B24)^2+(Q25/$B25)^2)/2) -> #DIV/0!
A28: 全統計參與(滿分三分) | D28: =IF(SQRT((D24/$B24)^2+(D25/$B25)^2)>2,3,3*SQRT((D24/$B24)^2+(D25/$B25)^2)/2) -> #DIV/0! | E28: =IF(SQRT((E24/$B24)^2+(E25/$B25)^2)>2,3,3*SQRT((E24/$B24)^2+(E25/$B25)^2)/2) -> #DIV/0! | F28: =IF(SQRT((F24/$B24)^2+(F25/$B25)^2)>2,3,3*SQRT((F24/$B24)^2+(F25/$B25)^2)/2) -> #DIV/0! | G28: =IF(SQRT((G24/$B24)^2+(G25/$B25)^2)>2,3,3*SQRT((G24/$B24)^2+(G25/$B25)^2)/2) -> #DIV/0! | H28: =IF(SQRT((H24/$B24)^2+(H25/$B25)^2)>2,3,3*SQRT((H24/$B24)^2+(H25/$B25)^2)/2) -> #DIV/0! | I28: =IF(SQRT((I24/$B24)^2+(I25/$B25)^2)>2,3,3*SQRT((I24/$B24)^2+(I25/$B25)^2)/2) -> #DIV/0! | J28: =IF(SQRT((J24/$B24)^2+(J25/$B25)^2)>2,3,3*SQRT((J24/$B24)^2+(J25/$B25)^2)/2) -> #DIV/0! | K28: =IF(SQRT((K24/$B24)^2+(K25/$B25)^2)>2,3,3*SQRT((K24/$B24)^2+(K25/$B25)^2)/2) -> #DIV/0! | ... Q28: =IF(SQRT((Q24/$B24)^2+(Q25/$B25)^2)>2,3,3*SQRT((Q24/$B24)^2+(Q25/$B25)^2)/2) -> #DIV/0!
A29: 去召委統計參與(滿分三分) | D29: =IF(SQRT((D24/$A24)^2+(D25/$A25)^2)>2,3,3*SQRT((D24/$A24)^2+(D25/$A25)^2)/2) -> #DIV/0! | E29: =IF(SQRT((E24/$A24)^2+(E25/$A25)^2)>2,3,3*SQRT((E24/$A24)^2+(E25/$A25)^2)/2) -> #DIV/0! | F29: =IF(SQRT((F24/$A24)^2+(F25/$A25)^2)>2,3,3*SQRT((F24/$A24)^2+(F25/$A25)^2)/2) -> #DIV/0! | G29: =IF(SQRT((G24/$A24)^2+(G25/$A25)^2)>2,3,3*SQRT((G24/$A24)^2+(G25/$A25)^2)/2) -> #DIV/0! | H29: =IF(SQRT((H24/$A24)^2+(H25/$A25)^2)>2,3,3*SQRT((H24/$A24)^2+(H25/$A25)^2)/2) -> #DIV/0! | I29: =IF(SQRT((I24/$A24)^2+(I25/$A25)^2)>2,3,3*SQRT((I24/$A24)^2+(I25/$A25)^2)/2) -> #DIV/0! | J29: =IF(SQRT((J24/$A24)^2+(J25/$A25)^2)>2,3,3*SQRT((J24/$A24)^2+(J25/$A25)^2)/2) -> #DIV/0! | K29: =IF(SQRT((K24/$A24)^2+(K25/$A25)^2)>2,3,3*SQRT((K24/$A24)^2+(K25/$A25)^2)/2) -> #DIV/0! | ... Q29: =IF(SQRT((Q24/$A24)^2+(Q25/$A25)^2)>2,3,3*SQRT((Q24/$A24)^2+(Q25/$A25)^2)/2) -> #DIV/0!
A31: 財政
C32: 政黨 | D32: 民進黨 | E32: 民進黨 | F32: 民進黨 | G32: 民進黨 | H32: 民進黨 | I32: 民進黨 | J32: 國民黨 | K32: 國民黨 | L32: 國民黨 | M32: 國民黨 | N32: 國民黨 | O32: 國民黨 | P32: 國民黨 | Q32: 民眾黨
A33: 平均 | B33: 去召委平均 | C33: 委員姓名 | D33: 賴惠員 | E33: 吳秉叡 | F33: 郭國文 | G33: 鍾佳濱 | H33: 王世堅 | I33: 李坤城 | J33: 賴士葆 | K33: 羅明才 | L33: 林德福 | M33: 顏寬恒 | N33: 陳玉珍 | O33: 李彥秀 | P33: 林思銘 | Q33: 黃珊珊
A34: =AVERAGE(D34:P34) -> 0 | B34: =AVERAGE(E34:F34,G34:I34,K34:Q34) -> 0 | C34: 次數 | D34: =' 財政'!D18 -> 0 | E34: =' 財政'!F18 -> 0 | F34: =' 財政'!H18 -> 0 | G34: =' 財政'!J18 -> 0 | H34: =' 財政'!L18 -> 0 | I34: =' 財政'!N18 -> 0 | J34: =' 財政'!P18 -> 0 | K34: =' 財政'!R18 -> 0 | L34: =' 財政'!T18 -> 0 | M34: =' 財政'!V18 -> 0 | N34: =' 財政'!X18 -> 0 | O34: =' 財政'!Z18 -> 0 | P34: =' 財政'!AB18 -> 0 | Q34: =' 財政'!AD18 -> 0
A35: =AVERAGE(D35:P35) -> 0 | B35: =AVERAGE(E35:F35,G35:I35,K35:Q35) -> 0 | C35: 字數 | D35: =' 財政'!E18 -> 0 | E35: =' 財政'!G18 -> 0 | F35: =' 財政'!I18 -> 0 | G35: =' 財政'!K18 -> 0 | H35: =' 財政'!M18 -> 0 | I35: =' 財政'!O18 -> 0 | J35: =' 財政'!Q18 -> 0 | K35: =' 財政'!S18 -> 0 | L35: =' 財政'!U18 -> 0 | M35: =' 財政'!W18 -> 0 | N35: =' 財政'!Y18 -> 0 | O35: =' 財政'!AA18 -> 0 | P35: =' 財政'!AC18 -> 0 | Q35: =' 財政'!AE18 -> 0
A36: 全統計參與(滿分五分) | D36: =IF(SQRT((D34/$A34)^2+(D35/$A35)^2)>2,5,5*SQRT((D34/$A34)^2+(D35/$A35)^2)/2) -> #DIV/0! | E36: =IF(SQRT((E34/$A34)^2+(E35/$A35)^2)>2,5,5*SQRT((E34/$A34)^2+(E35/$A35)^2)/2) -> #DIV/0! | F36: =IF(SQRT((F34/$A34)^2+(F35/$A35)^2)>2,5,5*SQRT((F34/$A34)^2+(F35/$A35)^2)/2) -> #DIV/0! | G36: =IF(SQRT((G34/$A34)^2+(G35/$A35)^2)>2,5,5*SQRT((G34/$A34)^2+(G35/$A35)^2)/2) -> #DIV/0! | H36: =IF(SQRT((H34/$A34)^2+(H35/$A35)^2)>2,5,5*SQRT((H34/$A34)^2+(H35/$A35)^2)/2) -> #DIV/0! | I36: =IF(SQRT((I34/$A34)^2+(I35/$A35)^2)>2,5,5*SQRT((I34/$A34)^2+(I35/$A35)^2)/2) -> #DIV/0! | J36: =IF(SQRT((J34/$A34)^2+(J35/$A35)^2)>2,5,5*SQRT((J34/$A34)^2+(J35/$A35)^2)/2) -> #DIV/0! | K36: =IF(SQRT((K34/$A34)^2+(K35/$A35)^2)>2,5,5*SQRT((K34/$A34)^2+(K35/$A35)^2)/2) -> #DIV/0! | ... Q36: =IF(SQRT((Q34/$A34)^2+(Q35/$A35)^2)>2,5,5*SQRT((Q34/$A34)^2+(Q35/$A35)^2)/2) -> #DIV/0!
A37: 去召委統計參與(滿分五分) | D37: =IF(SQRT((D34/$B34)^2+(D35/$B35)^2)>2,5,5*SQRT((D34/$B34)^2+(D35/$B35)^2)/2) -> #DIV/0! | E37: =IF(SQRT((E34/$B34)^2+(E35/$B35)^2)>2,5,5*SQRT((E34/$B34)^2+(E35/$B35)^2)/2) -> #DIV/0! | F37: =IF(SQRT((F34/$B34)^2+(F35/$B35)^2)>2,5,5*SQRT((F34/$B34)^2+(F35/$B35)^2)/2) -> #DIV/0! | G37: =IF(SQRT((G34/$B34)^2+(G35/$B35)^2)>2,5,5*SQRT((G34/$B34)^2+(G35/$B35)^2)/2) -> #DIV/0! | H37: =IF(SQRT((H34/$B34)^2+(H35/$B35)^2)>2,5,5*SQRT((H34/$B34)^2+(H35/$B35)^2)/2) -> #DIV/0! | I37: =IF(SQRT((I34/$B34)^2+(I35/$B35)^2)>2,5,5*SQRT((I34/$B34)^2+(I35/$B35)^2)/2) -> #DIV/0! | J37: =IF(SQRT((J34/$B34)^2+(J35/$B35)^2)>2,5,5*SQRT((J34/$B34)^2+(J35/$B35)^2)/2) -> #DIV/0! | K37: =IF(SQRT((K34/$B34)^2+(K35/$B35)^2)>2,5,5*SQRT((K34/$B34)^2+(K35/$B35)^2)/2) -> #DIV/0! | ... Q37: =IF(SQRT((Q34/$B34)^2+(Q35/$B35)^2)>2,5,5*SQRT((Q34/$B34)^2+(Q35/$B35)^2)/2) -> #DIV/0!
A38: 全統計參與(滿分三分) | D38: =IF(SQRT((D34/$A34)^2+(D35/$A35)^2)>2,3,3*SQRT((D34/$A34)^2+(D35/$A35)^2)/2) -> #DIV/0! | F38: =IF(SQRT((F34/$A34)^2+(F35/$A35)^2)>2,3,3*SQRT((F34/$A34)^2+(F35/$A35)^2)/2) -> #DIV/0! | G38: =IF(SQRT((G34/$A34)^2+(G35/$A35)^2)>2,3,3*SQRT((G34/$A34)^2+(G35/$A35)^2)/2) -> #DIV/0! | H38: =IF(SQRT((H34/$A34)^2+(H35/$A35)^2)>2,3,3*SQRT((H34/$A34)^2+(H35/$A35)^2)/2) -> #DIV/0! | I38: =IF(SQRT((I34/$A34)^2+(I35/$A35)^2)>2,3,3*SQRT((I34/$A34)^2+(I35/$A35)^2)/2) -> #DIV/0! | J38: =IF(SQRT((J34/$A34)^2+(J35/$A35)^2)>2,3,3*SQRT((J34/$A34)^2+(J35/$A35)^2)/2) -> #DIV/0! | K38: =IF(SQRT((K34/$A34)^2+(K35/$A35)^2)>2,3,3*SQRT((K34/$A34)^2+(K35/$A35)^2)/2) -> #DIV/0! | L38: =IF(SQRT((L34/$A34)^2+(L35/$A35)^2)>2,3,3*SQRT((L34/$A34)^2+(L35/$A35)^2)/2) -> #DIV/0! | M38: =IF(SQRT((M34/$A34)^2+(M35/$A35)^2)>2,3,3*SQRT((M34/$A34)^2+(M35/$A35)^2)/2) -> #DIV/0! | ... Q38: =IF(SQRT((Q34/$A34)^2+(Q35/$A35)^2)>2,3,3*SQRT((Q34/$A34)^2+(Q35/$A35)^2)/2) -> #DIV/0!
A39: 去召委統計參與(滿分三分) | D39: =IF(SQRT((D34/$B34)^2+(D35/$B35)^2)>2,3,3*SQRT((D34/$B34)^2+(D35/$B35)^2)/2) -> #DIV/0! | E39: =IF(SQRT((E34/$B34)^2+(E35/$B35)^2)>2,3,3*SQRT((E34/$B34)^2+(E35/$B35)^2)/2) -> #DIV/0! | F39: =IF(SQRT((F34/$B34)^2+(F35/$B35)^2)>2,3,3*SQRT((F34/$B34)^2+(F35/$B35)^2)/2) -> #DIV/0! | G39: =IF(SQRT((G34/$B34)^2+(G35/$B35)^2)>2,3,3*SQRT((G34/$B34)^2+(G35/$B35)^2)/2) -> #DIV/0! | H39: =IF(SQRT((H34/$B34)^2+(H35/$B35)^2)>2,3,3*SQRT((H34/$B34)^2+(H35/$B35)^2)/2) -> #DIV/0! | I39: =IF(SQRT((I34/$B34)^2+(I35/$B35)^2)>2,3,3*SQRT((I34/$B34)^2+(I35/$B35)^2)/2) -> #DIV/0! | J39: =IF(SQRT((J34/$B34)^2+(J35/$B35)^2)>2,3,3*SQRT((J34/$B34)^2+(J35/$B35)^2)/2) -> #DIV/0! | K39: =IF(SQRT((K34/$B34)^2+(K35/$B35)^2)>2,3,3*SQRT((K34/$B34)^2+(K35/$B35)^2)/2) -> #DIV/0! | ... Q39: =IF(SQRT((Q34/$B34)^2+(Q35/$B35)^2)>2,3,3*SQRT((Q34/$B34)^2+(Q35/$B35)^2)/2) -> #DIV/0!
A41: 教育文化
C42: 政黨 | D42: 民進黨 | E42: 民進黨 | F42: 民進黨 | G42: 民進黨 | H42: 民進黨 | I42: 民進黨 | J42: 民進黨 | K42: 國民黨 | L42: 國民黨 | M42: 國民黨 | N42: 國民黨 | O42: 國民黨 | P42: 國民黨 | Q42: 國民黨 | R42: 民眾黨
A43: 平均 | B43: 去召委平均 | C43: 委員姓名 | D43: 林宜瑾 | E43: 陳秀寳 | F43: 伍麗華 | G43: 吳沛憶 | H43: 范雲 | I43: 郭昱晴 | J43: 張雅琳 | K43: 葛如鈞 | L43: 萬美玲 | M43: 柯志恩 | N43: 羅廷瑋 | O43: 葉元之 | P43: 林沛祥 | Q43: 謝龍介 | R43: 劉書彬
...

Sheet  內政
A1: 日期 | B1: 會議名稱 | C1: 主席 | D1: 人工 | F1: 人工 | H1: 人工 | J1: 人工 | L1: 人工 | N1: 人工 | P1: 人工 | R1: 人工 | T1: 人工 | V1: 人工 | X1: 人工 | Z1: 人工 | AB1: 人工 | AD1: 人工
D2: 民進黨 | F2: 民進黨 | H2: 民進黨 | J2: 民進黨 | L2: 民進黨 | N2: 民進黨 | P2: 國民黨 | R2: 國民黨 | T2: 國民黨 | V2: 國民黨 | X2: 國民黨 | Z2: 國民黨 | AB2: 民眾黨 | AD2: 無黨籍
D3: 張宏陸 | F3: 吳琪銘 | H3: 王美惠 | J3: 蘇巧慧 | L3: 李柏毅 | N3: 黃捷 | P3: 牛煦庭 | R3: 徐欣瑩 | T3: 黃建賓 | V3: 張智倫 | X3: 許宇甄 | Z3: 丁學忠 | AB3: 麥玉珍 | AD3: 高金素梅
D4: 次 數 | E4: 字 數 | F4: 次 數 | G4: 字 數 | H4: 次 數 | I4: 字 數 | J4: 次 數 | K4: 字 數 | L4: 次 數 | M4: 字 數 | N4: 次 數 | O4: 字 數 | P4: 次 數 | Q4: 字 數 | R4: 次 數 | S4: 字 數 | T4: 次 數 | U4: 字 數 | V4: 次 數 | W4: 字 數 | X4: 次 數 | Y4: 字 數 | Z4: 次 數 | AA4: 字 數 | AB4: 次 數 | AC4: 字 數 | AD4: 次 數 | AE4: 字 數
A5: 114.12.17 | B5: 立法院第11屆第4會期內政委員會第16次全體委員會 | C5: 王美惠 | D5: 10 | E5: 689 | F5: 1 | G5: 231 | H5: 40 | I5: 1151 | J5: 4 | K5: 795 | L5: 3 | M5: 588 | N5: 5 | O5: 718 | P5: 0 | Q5: 0 | R5: 0 | S5: 0 | T5: 0 | U5: 0 | V5: 1 | W5: 278 | X5: 4 | Y5: 577 | Z5: 0 | AA5: 0 | AB5: 12 | AC5: 1621 | AD5: 0 | AE5: 0
D26: =SUM(D5:D25) -> 10 | E26: =SUM(E5:E25) -> 689 | F26: =SUM(F5:F25) -> 1 | G26: =SUM(G5:G25) -> 231 | H26: =SUM(H5:H25) -> 40 | I26: =SUM(I5:I25) -> 1151 | J26: =SUM(J5:J25) -> 4 | K26: =SUM(K5:K25) -> 795 | ... AE26: =SUM(AE5:AE25) -> 0

Sheet 外交國防
A1: 日期 | B1: 會議名稱 | C1: 主席 | D1: 人工 | F1: 人工 | H1: 人工 | J1: 人工 | L1: 人工 | N1: 人工 | P1: 人工 | R1: 人工 | T1: 人工 | V1: 人工 | X1: 人工 | Z1: 人工 | AB1: 人工
D2: 民進黨 | F2: 民進黨 | H2: 民進黨 | J2: 民進黨 | L2: 民進黨 | N2: 民進黨 | P2: 國民黨 | R2: 國民黨 | T2: 國民黨 | V2: 國民黨 | X2: 國民黨 | Z2: 國民黨 | AB2: 民眾黨
D3: 沈伯洋 | F3: 王定宇 | H3: 陳冠廷 | J3: 陳俊宇 | L3: 羅美玲 | N3: 林楚茵 | P3: 黃仁 | R3: 韓國瑜 | T3: 江啟臣 | V3: 馬文君 | X3: 徐巧芯 | Z3: 陳永康 | AB3: 林憶君
D4: 次 數 | E4: 字 數 | F4: 次 數 | G4: 字 數 | H4: 次 數 | I4: 字 數 | J4: 次 數 | K4: 字 數 | L4: 次 數 | M4: 字 數 | N4: 次 數 | O4: 字 數 | P4: 次 數 | Q4: 字 數 | R4: 次 數 | S4: 字 數 | T4: 次 數 | U4: 字 數 | V4: 次 數 | W4: 字 數 | X4: 次 數 | Y4: 字 數 | Z4: 次 數 | AA4: 字 數 | AB4: 次 數 | AC4: 字 數
D14: =SUM(D5:D13) -> 0 | E14: =SUM(E5:E13) -> 0 | F14: =SUM(F5:F13) -> 0 | G14: =SUM(G5:G13) -> 0 | H14: =SUM(H5:H13) -> 0 | I14: =SUM(I5:I13) -> 0 | J14: =SUM(J5:J13) -> 0 | K14: =SUM(K5:K13) -> 0 | ... AC14: =SUM(AC5:AC13) -> 0

Sheet 經濟
A1: 日期 | B1: 會議名稱 | C1: 主席 | D1: 人工 | F1: 人工 | H1: 人工 | J1: 人工 | L1: 人工 | N1: 人工 | P1: 人工 | R1: 人工 | T1: 人工 | V1: 人工 | X1: 人工 | Z1: 人工 | AB1: 人工 | AD1: 人工
D2: 民進黨 | F2: 民進黨 | H2: 民進黨 | J2: 民進黨 | L2: 民進黨 | N2: 民進黨 | P2: 國民黨 | R2: 國民黨 | T2: 國民黨 | V2: 國民黨 | X2: 國民黨 | Z2: 國民黨 | AB2: 民眾黨 | AD2: 無黨籍
D3: 蔡易餘 | F3: 林岱樺 | H3: 邱議瑩 | J3: 邱志偉 | L3: 陳亭妃 | N3: 賴瑞隆 | P3: 謝衣鳯 | R3: 楊瓊瓔 | T3: 鄭天財 | V3: 呂玉玲 | X3: 張嘉郡 | Z3: 鄭正鈐 | AB3: 張啓楷 | AD3: 陳超明
D4: 次 數 | E4: 字 數 | F4: 次 數 | G4: 字 數 | H4: 次 數 | I4: 字 數 | J4: 次 數 | K4: 字 數 | L4: 次 數 | M4: 字 數 | N4: 次 數 | O4: 字 數 | P4: 次 數 | Q4: 字 數 | R4: 次 數 | S4: 字 數 | T4: 次 數 | U4: 字 數 | V4: 次 數 | W4: 字 數 | X4: 次 數 | Y4: 字 數 | Z4: 次 數 | AA4: 字 數 | AB4: 次 數 | AC4: 字 數 | AD4: 次 數 | AE4: 字 數
D13: =SUM(D5:D12) -> 0 | E13: =SUM(E5:E12) -> 0 | F13: =SUM(F5:F12) -> 0 | G13: =SUM(G5:G12) -> 0 | H13: =SUM(H5:H12) -> 0 | I13: =SUM(I5:I12) -> 0 | J13: =SUM(J5:J12) -> 0 | K13: =SUM(K5:K12) -> 0 | ... AE13: =SUM(AE5:AE12) -> 0

Sheet  財政
A1: 日期 | B1: 會議名稱 | C1: 主席 | D1: 人工 | F1: 人工 | H1: 人工 | J1: 人工 | L1: 人工 | N1: 人工 | P1: 人工 | R1: 人工 | T1: 人工 | V1: 人工 | X1: 人工 | Z1: 人工 | AB1: 人工 | AD1: 人工
D2: 民進黨 | F2: 民進黨 | H2: 民進黨 | J2: 民進黨 | L2: 民進黨 | N2: 民進黨 | P2: 國民黨 | R2: 國民黨 | T2: 國民黨 | V2: 國民黨 | X2: 國民黨 | Z2: 國民黨 | AB2: 國民黨 | AD2: 民眾黨
D3: 賴惠員 | F3: 吳秉叡 | H3: 郭國文 | J3: 鍾佳濱 | L3: 王世堅 | N3: 李坤城 | P3: 賴士葆 | R3: 羅明才 | T3: 林德福 | V3: 顏寬恒 | X3: 陳玉珍 | Z3: 李彥秀 | AB3: 林思銘 | AD3: 黃珊珊
D4: 次 數 | E4: 字 數 | F4: 次 數 | G4: 字 數 | H4: 次 數 | I4: 字 數 | J4: 次 數 | K4: 字 數 | L4: 次 數 | M4: 字 數 | N4: 次 數 | O4: 字 數 | P4: 次 數 | Q4: 字 數 | R4: 次 數 | S4: 字 數 | T4: 次 數 | U4: 字 數 | V4: 次 數 | W4: 字 數 | X4: 次 數 | Y4: 字 數 | Z4: 次 數 | AA4: 字 數 | AB4: 次 數 | AC4: 字 數 | AD4: 次 數 | AE4: 字 數
D18: =SUM(D5:D17) -> 0 | E18: =SUM(E5:E17) -> 0 | F18: =SUM(F5:F17) -> 0 | G18: =SUM(G5:G17) -> 0 | H18: =SUM(H5:H17) -> 0 | I18: =SUM(I5:I17) -> 0 | J18: =SUM(J5:J17) -> 0 | K18: =SUM(K5:K17) -> 0 | ... AE18: =SUM(AE5:AE17) -> 0

Sheet 教育文化
A1: 日期 | B1: 會議名稱 | C1: 主席 | D1: 人工 | F1: 人工 | H1: 人工 | J1: 人工 | L1: 人工 | N1: 人工 | P1: 人工 | R1: 人工 | T1: 人工 | V1: 人工 | X1: 人工 | Z1: 人工 | AB1: 人工 | AD1: 人工 | AF1: 人工
D2: 民進黨 | F2: 民進黨 | H2: 民進黨 | J2: 民進黨 | L2: 民進黨 | N2: 民進黨 | P2: 民進黨 | R2: 國民黨 | T2: 國民黨 | V2: 國民黨 | X2: 國民黨 | Z2: 國民黨 | AB2: 國民黨 | AD2: 國民黨 | AF2: 民眾黨
D3: 林宜瑾 | F3: 陳秀寳 | H3: 伍麗華 | J3: 吳沛憶 | L3: 范雲 | N3: 郭昱晴 | P3: 張雅琳 | R3: 葛如鈞 | T3: 萬美玲 | V3: 柯志恩 | X3: 羅廷瑋 | Z3: 葉元之 | AB3: 林沛祥 | AD3: 謝龍介 | AF3: 劉書彬
D4: 次 數 | E4: 字 數 | F4: 次 數 | G4: 字 數 | H4: 次 數 | I4: 字 數 | J4: 次 數 | K4: 字 數 | L4: 次 數 | M4: 字 數 | N4: 次 數 | O4: 字 數 | P4: 次 數 | Q4: 字 數 | R4: 次 數 | S4: 字 數 | T4: 次 數 | U4: 字 數 | V4: 次 數 | W4: 字 數 | X4: 次 數 | Y4: 字 數 | Z4: 次 數 | AA4: 字 數 | AB4: 次 數 | AC4: 字 數 | AD4: 次 數 | AE4: 字 數 | AF4: 次 數 | AG4: 字 數
D15: =SUM(D5:D14) -> 0 | E15: =SUM(E5:E14) -> 0 | F15: =SUM(F5:F14) -> 0 | G15: =SUM(G5:G14) -> 0 | H15: =SUM(H5:H14) -> 0 | I15: =SUM(I5:I14) -> 0 | J15: =SUM(J5:J14) -> 0 | K15: =SUM(K5:K14) -> 0 | ... AG15: =SUM(AG5:AG14) -> 0

Sheet 交通
A1: 日期 | B1: 會議名稱 | C1: 主席 | D1: 人工 | F1: 人工 | H1: 人工 | J1: 人工 | L1: 人工 | N1: 人工 | P1: 人工 | R1: 人工 | T1: 人工 | V1: 人工 | X1: 人工 | Z1: 人工 | AB1: 人工 | AD1: 人工 | AF1: 人工
D2: 民進黨 | F2: 民進黨 | H2: 民進黨 | J2: 民進黨 | L2: 民進黨 | N2: 民進黨 | P2: 民進黨 | R2: 國民黨 | T2: 國民黨 | V2: 國民黨 | X2: 國民黨 | Z2: 國民黨 | AB2: 國民黨 | AD2: 國民黨 | AF2: 民眾黨
D3: 許智傑 | F3: 李昆澤 | H3: 陳素月 | J3: 林俊憲 | L3: 蔡其昌 | N3: 何欣純 | P3: 徐富癸 | R3: 陳雪生 | T3: 魯明哲 | V3: 洪孟楷 | X3: 黃健豪 | Z3: 廖先翔 | AB3: 邱若華 | AD3: 游顥 | AF3: 林國成
D4: 次 數 | E4: 字 數 | F4: 次 數 | G4: 字 數 | H4: 次 數 | I4: 字 數 | J4: 次 數 | K4: 字 數 | L4: 次 數 | M4: 字 數 | N4: 次 數 | O4: 字 數 | P4: 次 數 | Q4: 字 數 | R4: 次 數 | S4: 字 數 | T4: 次 數 | U4: 字 數 | V4: 次 數 | W4: 字 數 | X4: 次 數 | Y4: 字 數 | Z4: 次 數 | AA4: 字 數 | AB4: 次 數 | AC4: 字 數 | AD4: 次 數 | AE4: 字 數 | AF4: 次 數 | AG4: 字 數
D15: =SUM(D5:D14) -> 0 | E15: =SUM(E5:E14) -> 0 | F15: =SUM(F5:F14) -> 0 | G15: =SUM(G5:G14) -> 0 | H15: =SUM(H5:H14) -> 0 | I15: =SUM(I5:I14) -> 0 | J15: =SUM(J5:J14) -> 0 | K15: =SUM(K5:K14) -> 0 | ... AG15: =SUM(AG5:AG14) -> 0

Sheet  司法法制
A1: 日期 | B1: 會議名稱 | C1: 主席 | D1: 人工 | F1: 人工 | H1: 人工 | J1: 人工 | L1: 人工 | N1: 人工 | P1: 人工 | R1: 人工 | T1: 人工 | V1: 人工 | X1: 人工 | Z1: 人工 | AB1: 人工
D2: 民進黨 | F2: 民進黨 | H2: 民進黨 | J2: 民進黨 | L2: 民進黨 | N2: 民進黨 | P2: 國民黨 | R2: 國民黨 | T2: 國民黨 | V2: 國民黨 | X2: 國民黨 | Z2: 國民黨 | AB2: 民眾黨
D3: 莊瑞雄 | F3: 柯建銘 | H3: 吳思瑤 | J3: 陳培瑜 | L3: 沈發惠 | N3: 王義川 | P3: 吳宗憲 | R3: 傅崐萁 | T3: 王鴻薇 | V3: 羅智強 | X3: 翁曉玲 | Z3: 林倩綺 | AB3: 黃國昌
D4: 次 數 | E4: 字 數 | F4: 次 數 | G4: 字 數 | H4: 次 數 | I4: 字 數 | J4: 次 數 | K4: 字 數 | L4: 次 數 | M4: 字 數 | N4: 次 數 | O4: 字 數 | P4: 次 數 | Q4: 字 數 | R4: 次 數 | S4: 字 數 | T4: 次 數 | U4: 字 數 | V4: 次 數 | W4: 字 數 | X4: 次 數 | Y4: 字 數 | Z4: 次 數 | AA4: 字 數 | AB4: 次 數 | AC4: 字 數
D17: =SUM(D5:D16) -> 0 | E17: =SUM(E5:E16) -> 0 | F17: =SUM(F5:F16) -> 0 | G17: =SUM(G5:G16) -> 0 | H17: =SUM(H5:H16) -> 0 | I17: =SUM(I5:I16) -> 0 | J17: =SUM(J5:J16) -> 0 | K17: =SUM(K5:K16) -> 0 | ... AC17: =SUM(AC5:AC16) -> 0

Sheet 社福衛環
A1: 日期 | B1: 會議名稱 | C1: 主席 | D1: 人工 | F1: 人工 | H1: 人工 | J1: 人工 | L1: 人工 | N1: 人工 | P1: 人工 | R1: 人工 | T1: 人工 | V1: 人工 | X1: 人工 | Z1: 人工 | AB1: 人工 | AD1: 人工 | AF1: 人工
D2: 民進黨 | F2: 民進黨 | H2: 民進黨 | J2: 民進黨 | L2: 民進黨 | N2: 民進黨 | P2: 民進黨 | R2: 國民黨 | T2: 國民黨 | V2: 國民黨 | X2: 國民黨 | Z2: 國民黨 | AB2: 國民黨 | AD2: 國民黨 | AF2: 民眾黨
D3: 劉建國 | F3: 楊曜 | H3: 陳瑩 | J3: 林淑芬 | L3: 黃秀芳 | N3: 王正旭 | P3: 林月琴 | R3: 蘇清泉 | T3: 王育敏 | V3: 廖偉翔 | X3: 陳菁徽 | Z3: 盧縣一 | AB3: 邱鎮軍 | AD3: 涂權吉 | AF3: 陳昭姿
D4: 次 數 | E4: 字 數 | F4: 次 數 | G4: 字 數 | H4: 次 數 | I4: 字 數 | J4: 次 數 | K4: 字 數 | L4: 次 數 | M4: 字 數 | N4: 次 數 | O4: 字 數 | P4: 次 數 | Q4: 字 數 | R4: 次 數 | S4: 字 數 | T4: 次 數 | U4: 字 數 | V4: 次 數 | W4: 字 數 | X4: 次 數 | Y4: 字 數 | Z4: 次 數 | AA4: 字 數 | AB4: 次 數 | AC4: 字 數 | AD4: 次 數 | AE4: 字 數 | AF4: 次 數 | AG4: 字 數
D15: =SUM(D5:D14) -> 0 | E15: =SUM(E5:E14) -> 0 | F15: =SUM(F5:F14) -> 0 | G15: =SUM(G5:G14) -> 0 | H15: =SUM(H5:H14) -> 0 | I15: =SUM(I5:I14) -> 0 | J15: =SUM(J5:J14) -> 0 | K15: =SUM(K5:K14) -> 0 | ... AG15: =SUM(AG5:AG14) -> 0
